Workbook

Sheet LX02_DATA
A1: OWNER | B1: OWNER_ROLE | C1: ENTITELED | D1: ENTITLED_ROLE | E1: MATNR | F1: HUTYP | G1: PMAT | H1: GR_DATE | I1: VFDAT | J1: LGPLA | K1: SSCC | L1: UNIT | M1: QUAN | N1: CAT | O1: EXTNO | P1: Storage Type | Q1: Storage Bin | R1: Material | S1: Material Description | T1: Storage Unit | U1: Batch | V1: SLED/BBD | W1: Storage Location | X1: Storage Unit Type | Y1: Stock Category | Z1: Special Stock | AA1: Av. Stock WM UoM | AB1: WM unit | AC1: Base Unit of Measure | AD1: GR Date | AE1: GR Date | AF1: Inventory active | AG1: Inventory record | AH1: Inventory record | AI1: Last inventory | AJ1: Weight
A2: NE00 | B2: BP | C2: NE00 | D2: BP | E2: =VLOOKUP(R2,MATERIAL_MAPPING!A:B,2,FALSE) -> 8064 | F2: =RIGHT(G2,2) -> E1 | G2: =VLOOKUP(X2,STORAGE_UNIT_TYPE_MAPPING!A:B,2,FALSE) -> NPALLET-E1 | H2: =TEXT(AE2,"yyyymmdd") -> 20240730 | I2: =TEXT(V2,"yyyymmdd") -> 20260331 | J2: =VLOOKUP(Q2,BIN_MAPPING!A:B,2,FALSE) -> 19-040-1 | K2: 350103471816156564 | L2: CS | M2: 20 | N2: 01 | O2: X | P2: PCK | Q2: 19-40-A | R2: 12326084 | S2: PEPTAMEN JUNIOR ACE002-2 12x400g GB | T2: 350103471816156564 | U2: 40620017A1 | V2: 46112 | W2: 0001 | X2: EUR | AA2: 20 | AB2: CS | AD2: 45503 | AE2: 45503 | AI2: 123.36
A3: NE00 | B3: BP | C3: NE00 | D3: BP | E3: =VLOOKUP(R3,MATERIAL_MAPPING!A:B,2,FALSE) -> 8506 | F3: =RIGHT(G3,2) -> E1 | G3: =VLOOKUP(X3,STORAGE_UNIT_TYPE_MAPPING!A:B,2,FALSE) -> NPALLET-E1 | H3: =TEXT(AE3,"yyyymmdd") -> 20241001 | I3: =TEXT(V3,"yyyymmdd") -> 20250930 | J3: =VLOOKUP(Q3,BIN_MAPPING!A:B,2,FALSE) -> 19-042-1 | K3: 350103471816772245 | L3: CS | M3: 47 | N3: 01 | O3: X | P3: PCK | Q3: 19-42-A | R3: 12511297 | S3: VITLPRT MarineColla Stp+Box 14(10x10g)GB | T3: 350103471816772245 | U3: 2325700002 | V3: 45930 | W3: 0001 | X3: EUR | AA3: 47 | AB3: CS | AD3: 45566 | AE3: 45566 | AI3: 105.28
A4: NE00 | B4: BP | C4: NE00 | D4: BP | E4: =VLOOKUP(R4,MATERIAL_MAPPING!A:B,2,FALSE) -> 8539 | F4: =RIGHT(G4,2) -> E1 | G4: =VLOOKUP(X4,STORAGE_UNIT_TYPE_MAPPING!A:B,2,FALSE) -> NPALLET-E1 | H4: =TEXT(AE4,"yyyymmdd") -> 20240909 | I4: =TEXT(V4,"yyyymmdd") -> 20250722 | J4: =VLOOKUP(Q4,BIN_MAPPING!A:B,2,FALSE) -> 19-044-1 | K4: 350103471816506369 | L4: CS | M4: 7 | N4: 01 | O4: X | P4: PCK | Q4: 19-44-A | R4: 12513514 | S4: PEPTAMEN JNR PHGG Van 12x500ml XI | T4: 350103471816506369 | U4: 4209428220 | V4: 45860 | W4: 0001 | X4: EUR | AA4: 7 | AB4: CS | AD4: 45544 | AE4: 45544 | AI4: 47.796
A5: NE00 | B5: BP | C5: NE00 | D5: BP | E5: =VLOOKUP(R5,MATERIAL_MAPPING!A:B,2,FALSE) -> 8142 | F5: =RIGHT(G5,2) -> E1 | G5: =VLOOKUP(X5,STORAGE_UNIT_TYPE_MAPPING!A:B,2,FALSE) -> NPALLET-E1 | H5: =TEXT(AE5,"yyyymmdd") -> 20241008 | I5: =TEXT(V5,"yyyymmdd") -> 20250601 | J5: =VLOOKUP(Q5,BIN_MAPPING!A:B,2,FALSE) -> 19-045-1 | K5: 350103471816883958 | L5: CS | M5: 6 | N5: 01 | O5: X | P5: PCK | Q5: 19-45-A | R5: 12383174 | S5: PEPTAMEN Neutral Dual 9x1L N1 XE | T5: 350103471816883958 | U5: 4158428220 | V5: 45809 | W5: 0001 | X5: EUR | AA5: 6 | AB5: CS | AD5: 45573 | AE5: 45573 | AI5: 62.1
A6: NE00 | B6: BP | C6: NE00 | D6: BP | E6: =VLOOKUP(R6,MATERIAL_MAPPING!A:B,2,FALSE) -> 8504 | F6: =RIGHT(G6,2) -> E1 | G6: =VLOOKUP(X6,STORAGE_UNIT_TYPE_MAPPING!A:B,2,FALSE) -> NPALLET-E1 | H6: =TEXT(AE6,"yyyymmdd") -> 20240918 | I6: =TEXT(V6,"yyyymmdd") -> 20260430 | J6: =VLOOKUP(Q6,BIN_MAPPING!A:B,2,FALSE) -> 19-046-1 | K6: 350103471816603020 | L6: CS | M6: 8 | N6: 01 | O6: X | P6: PCK | Q6: 19-46-A | R6: 12511278 | S6: VITLPRT CollPep Stp+Box 14(10x10g) GB | T6: 350103471816603020 | U6: 2410700002 | V6: 46142 | W6: 0001 | X6: EUR | AA6: 8 | AB6: CS | AD6: 45553 | AE6: 45553 | AI6: 17.92
A7: NE00 | B7: BP | C7: NE00 | D7: BP | E7: =VLOOKUP(R7,MATERIAL_MAPPING!A:B,2,FALSE) -> 8156 | F7: =RIGHT(G7,2) -> E1 | G7: =VLOOKUP(X7,STORAGE_UNIT_TYPE_MAPPING!A:B,2,FALSE) -> NPALLET-E1 | H7: =TEXT(AE7,"yyyymmdd") -> 20241008 | I7: =TEXT(V7,"yyyymmdd") -> 20250824 | J7: =VLOOKUP(Q7,BIN_MAPPING!A:B,2,FALSE) -> 19-047-1 | K7: 350103471816883736 | L7: CS | M7: 29 | N7: 01 | O7: X | P7: PCK | Q7: 19-47-A | R7: 12393877 | S7: PEPTAMEN JUNIOR 0.6 12x500ml XE | T7: 350103471816883736 | U7: 4242428221 | V7: 45893 | W7: 0001 | X7: EUR | AA7: 29 | AB7: CS | AD7: 45573 | AE7: 45573 | AI7: 191.4
A8: NE00 | B8: BP | C8: NE00 | D8: BP | E8: =VLOOKUP(R8,MATERIAL_MAPPING!A:B,2,FALSE) -> 10883 | F8: =RIGHT(G8,2) -> E1 | G8: =VLOOKUP(X8,STORAGE_UNIT_TYPE_MAPPING!A:B,2,FALSE) -> NPALLET-E1 | H8: =TEXT(AE8,"yyyymmdd") -> 20240917 | I8: =TEXT(V8,"yyyymmdd") -> 20260831 | J8: =VLOOKUP(Q8,BIN_MAPPING!A:B,2,FALSE) -> 19-048-1 | K8: 376130300220453386 | L8: CS | M8: 48 | N8: 01 | O8: X | P8: PCK | Q8: 19-48-A | R8: 12454872 | S8: ALFAMINO ACS019 6x400g N1 GB | T8: 376130300220453386 | U8: 42360017Y1 | V8: 46265 | W8: 0001 | X8: EUR | AA8: 48 | AB8: CS | AD8: 45552 | AE8: 45552 | AI8: 151.776
A9: NE00 | B9: BP | C9: NE00 | D9: BP | E9: =VLOOKUP(R9,MATERIAL_MAPPING!A:B,2,FALSE) -> 8143 | F9: =RIGHT(G9,2) -> E1 | G9: =VLOOKUP(X9,STORAGE_UNIT_TYPE_MAPPING!A:B,2,FALSE) -> NPALLET-E1 | H9: =TEXT(AE9,"yyyymmdd") -> 20240909 | I9: =TEXT(V9,"yyyymmdd") -> 20250730 | J9: =VLOOKUP(Q9,BIN_MAPPING!A:B,2,FALSE) -> 19-049-1 | K9: 350103471816411458 | L9: CS | M9: 1 | N9: 01 | O9: X | P9: PCK | Q9: 19-49-A | R9: 12383265 | S9: PEPTAMEN HN Neutral Dual 12x500ml N1 XI | T9: 350103471816411458 | U9: 4217428220 | V9: 45868 | W9: 0001 | X9: EUR | AA9: 1 | AB9: CS | AD9: 45544 | AE9: 45544 | AI9: 6.852
A10: NE00 | B10: BP | C10: NE00 | D10: BP | E10: =VLOOKUP(R10,MATERIAL_MAPPING!A:B,2,FALSE) -> 10913 | F10: =RIGHT(G10,2) -> E1 | G10: =VLOOKUP(X10,STORAGE_UNIT_TYPE_MAPPING!A:B,2,FALSE) -> NPALLET-E1 | H10: =TEXT(AE10,"yyyymmdd") -> 20240821 | I10: =TEXT(V10,"yyyymmdd") -> 20250228 | J10: =VLOOKUP(Q10,BIN_MAPPING!A:B,2,FALSE) -> 19-050-1 | K10: 376130308202572629 | L10: CS | M10: 18 | N10: 01 | O10: X | P10: PCK | Q10: 19-50-A | R10: 12464610 | S10: MINAMI Liquid Kids 12x100ml GB | T10: 376130308202572629 | U10: 2362737 | V10: 45716 | W10: 0001 | X10: EUR | AA10: 18 | AB10: CS | AD10: 45525 | AE10: 45525 | AI10: 38.88
A11: NE00 | B11: BP | C11: NE00 | D11: BP | E11: =VLOOKUP(R11,MATERIAL_MAPPING!A:B,2,FALSE) -> 8141 | F11: =RIGHT(G11,2) -> E1 | G11: =VLOOKUP(X11,STORAGE_UNIT_TYPE_MAPPING!A:B,2,FALSE) -> NPALLET-E1 | H11: =TEXT(AE11,"yyyymmdd") -> 20240916 | I11: =TEXT(V11,"yyyymmdd") -> 20250701 | J11: =VLOOKUP(Q11,BIN_MAPPING!A:B,2,FALSE) -> 19-051-1 | K11: 350103471816360046 | L11: CS | M11: 15 | N11: 01 | O11: X | P11: PCK | Q11: 19-51-A | R11: 12383170 | S11: PEPTAMEN Neutral Dual 12x500ml N1 XI | T11: 350103471816360046 | U11: 4188428220 | V11: 45839 | W11: 0001 | X11: EUR | AA11: 15 | AB11: CS | AD11: 45551 | AE11: 45551 | AI11: 100.62
A12: NE00 | B12: BP | C12: NE00 | D12: BP | E12: =VLOOKUP(R12,MATERIAL_MAPPING!A:B,2,FALSE) -> 8144 | F12: =RIGHT(G12,2) -> E1 | G12: =VLOOKUP(X12,STORAGE_UNIT_TYPE_MAPPING!A:B,2,FALSE) -> NPALLET-E1 | H12: =TEXT(AE12,"yyyymmdd") -> 20240918 | I12: =TEXT(V12,"yyyymmdd") -> 20250710 | J12: =VLOOKUP(Q12,BIN_MAPPING!A:B,2,FALSE) -> 19-053-1 | K12: 340055001841986741 | L12: CS | M12: 48 | N12: 01 | O12: X | P12: PCK | Q12: 19-53-A | R12: 12383271 | S12: PEPTAMEN JNRADV Ntr Dual 12x500ml N1 XI | T12: 340055001841986741 | U12: 4197428228 | V12: 45848 | W12: 0001 | X12: EUR | AA12: 48 | AB12: CS | AD12: 45553 | AE12: 45553 | AI12: 321.984
A13: NE00 | B13: BP | C13: NE00 | D13: BP | E13: =VLOOKUP(R13,MATERIAL_MAPPING!A:B,2,FALSE) -> 10888 | F13: =RIGHT(G13,2) -> I1 | G13: =VLOOKUP(X13,STORAGE_UNIT_TYPE_MAPPING!A:B,2,FALSE) -> NPALLET-I1 | H13: =TEXT(AE13,"yyyymmdd") -> 20241011 | I13: =TEXT(V13,"yyyymmdd") -> 20270930 | J13: =VLOOKUP(Q13,BIN_MAPPING!A:B,2,FALSE) -> 19-054-1 | K13: 376130308202812541 | L13: CS | M13: 6 | N13: 01 | O13: X | P13: PCK | Q13: 19-54-A | R13: 12468218 | S13: VP Collagen Peptides 6x567g GB | T13: 376130308202812541 | U13: 4065635 | V13: 46660 | W13: 0001 | X13: LPR | AA13: 6 | AB13: CS | AD13: 45576 | AE13: 45576 | AI13: 24.984
... A70: NE00 | B70: BP | C70: NE00 | D70: BP | E70: =VLOOKUP(R70,MATERIAL_MAPPING!A:B,2,FALSE) -> 9460 | F70: =RIGHT(G70,2) -> I1 | G70: =VLOOKUP(X70,STORAGE_UNIT_TYPE_MAPPING!A:B,2,FALSE) -> NPALLET-I1 | H70: =TEXT(AE70,"yyyymmdd") -> 20240926 | I70: =TEXT(V70,"yyyymmdd") -> 20250930 | J70: =VLOOKUP(Q70,BIN_MAPPING!A:B,2,FALSE) -> 20-006-5 | K70: 350103474955933928 | L70: CS | M70: 196 | N70: 01 | O70: X | P70: AG | Q70: 20-06-E | R70: 12571740 | S70: NESCAFE CAPPUCCINO 8Sac 6x124g GB | T70: 350103474955933928 | U70: 42521091R | V70: 45930 | W70: 0001 | X70: LPR | AA70: 196 | AB70: CS | AD70: 45561 | AE70: 45561 | AI70: 190.653
A71: NE00 | B71: BP | C71: NE00 | D71: BP | E71: =VLOOKUP(R71,MATERIAL_MAPPING!A:B,2,FALSE) -> 8942 | F71: =RIGHT(G71,2) -> I1 | G71: =VLOOKUP(X71,STORAGE_UNIT_TYPE_MAPPING!A:B,2,FALSE) -> NPALLET-I1 | H71: =TEXT(AE71,"yyyymmdd") -> 20230926 | I71: =TEXT(V71,"yyyymmdd") -> 20241130 | J71: =VLOOKUP(Q71,BIN_MAPPING!A:B,2,FALSE) -> 20-006-6 | K71: 384101002222848148 | L71: CS | M71: 61 | N71: 08 | O71: X | P71: AG | Q71: 20-06-F | R71: 12538639 | S71: CERELAC Rice FA1122-1 6x400g XB | T71: 384101002222848148 | U71: 31830291 | V71: 45626 | W71: 0001 | X71: LPR | Y71: S | AA71: 61 | AB71: CS | AD71: 45195 | AE71: 45195 | AI71: 183
A72: NE00 | B72: BP | C72: NE00 | D72: BP | E72: =VLOOKUP(R72,MATERIAL_MAPPING!A:B,2,FALSE) -> 9729 | F72: =RIGHT(G72,2) -> I1 | G72: =VLOOKUP(X72,STORAGE_UNIT_TYPE_MAPPING!A:B,2,FALSE) -> NPALLET-I1 | H72: =TEXT(AE72,"yyyymmdd") -> 20240807 | I72: =TEXT(V72,"yyyymmdd") -> 20250430 | J72: =VLOOKUP(Q72,BIN_MAPPING!A:B,2,FALSE) -> 20-007-1 | K72: 350103475120184787 | L72: CS | M72: 41 | N72: 01 | O72: X | P72: PCK | Q72: 20-07-A | R72: 12587761 | S72: NESTLE White Selection Box 8x199g XB | T72: 350103475120184787 | U72: 41834826 | V72: 45777 | W72: 0001 | X72: LPR | AA72: 41 | AB72: CS | AD72: 45511 | AE72: 45511 | AI72: 80.483
A73: NE00 | B73: BP | C73: NE00 | D73: BP | E73: =VLOOKUP(R73,MATERIAL_MAPPING!A:B,2,FALSE) -> 9708 | F73: =RIGHT(G73,2) -> I1 | G73: =VLOOKUP(X73,STORAGE_UNIT_TYPE_MAPPING!A:B,2,FALSE) -> NPALLET-I1 | H73: =TEXT(AE73,"yyyymmdd") -> 20241002 | I73: =TEXT(V73,"yyyymmdd") -> 20250731 | J73: =VLOOKUP(Q73,BIN_MAPPING!A:B,2,FALSE) -> 20-007-2 | K73: 350018900021413450 | L73: CS | M73: 18 | N73: 01 | O73: X | P73: AG | Q73: 20-07-B | R73: 12586771 | S73: COOKIE CRISP Cereal 14x500g N4 XB | T73: 350018900021413450 | U73: 42063156 | V73: 45869 | W73: 0001 | X73: LPR | AA73: 18 | AB73: CS | AD73: 45567 | AE73: 45567 | AI73: 145.152
A74: NE00 | B74: BP | C74: NE00 | D74: BP | E74: =VLOOKUP(R74,MATERIAL_MAPPING!A:B,2,FALSE) -> 10441 | F74: =RIGHT(G74,2) -> I1 | G74: =VLOOKUP(X74,STORAGE_UNIT_TYPE_MAPPING!A:B,2,FALSE) -> NPALLET-I1 | H74: =TEXT(AE74,"yyyymmdd") -> 20240923 | I74: =TEXT(V74,"yyyymmdd") -> 20260831 | J74: =VLOOKUP(Q74,BIN_MAPPING!A:B,2,FALSE) -> 20-007-3 | K74: 350001612890863181 | L74: CS | M74: 105 | N74: 01 | O74: X | P74: AG | Q74: 20-07-C | R74: 12461268 | S74: WINALOT SNRCiG MVChkn&Crt10 4(12x100g)GB | T74: 350001612890863181 | U74: 4238096203 | V74: 46265 | W74: 0001 | X74: CHP | AA74: 105 | AB74: CS | AD74: 45558 | AE74: 45558 | AI74: 567
A75: NE00 | B75: BP | C75: NE00 | D75: BP | E75: =VLOOKUP(R75,MATERIAL_MAPPING!A:B,2,FALSE) -> 10761 | F75: =RIGHT(G75,2) -> I1 | G75: =VLOOKUP(X75,STORAGE_UNIT_TYPE_MAPPING!A:B,2,FALSE) -> NPALLET-I1 | H75: =TEXT(AE75,"yyyymmdd") -> 20240912 | I75: =TEXT(V75,"yyyymmdd") -> 20260731 | J75: =VLOOKUP(Q75,BIN_MAPPING!A:B,2,FALSE) -> 20-007-4 | K75: 376130308202784619 | L75: CS | M75: 105 | N75: 01 | O75: X | P75: AG | Q75: 20-07-D | R75: 12573484 | S75: FELIX CiJ MV Fish Selection 4(12x85g) XB | T75: 376130308202784619 | U75: 4245T931 | V75: 46234 | W75: 0001 | X75: CHP | AA75: 105 | AB75: CS | AD75: 45547 | AE75: 45547 | AI75: 508.2
A76: NE00 | B76: BP | C76: NE00 | D76: BP | E76: =VLOOKUP(R76,MATERIAL_MAPPING!A:B,2,FALSE) -> 10219 | F76: =RIGHT(G76,2) -> I1 | G76: =VLOOKUP(X76,STORAGE_UNIT_TYPE_MAPPING!A:B,2,FALSE) -> NPALLET-I1 | H76: =TEXT(AE76,"yyyymmdd") -> 20241003 | I76: =TEXT(V76,"yyyymmdd") -> 20260228 | J76: =VLOOKUP(Q76,BIN_MAPPING!A:B,2,FALSE) -> 20-007-5 | K76: 350001610329564081 | L76: CS | M76: 80 | N76: 01 | O76: X | P76: AG | Q76: 20-07-E | R76: 12296840 | S76: ONE ADULT Cat Salmon&WhlG 4x800g N1 GB | T76: 350001610329564081 | U76: 4215093105 | V76: 46081 | W76: 0001 | X76: CHP | AA76: 80 | AB76: CS | AD76: 45568 | AE76: 45568 | AI76: 265.6
A77: NE00 | B77: BP | C77: NE00 | D77: BP | E77: =VLOOKUP(R77,MATERIAL_MAPPING!A:B,2,FALSE) -> 9164 | F77: =RIGHT(G77,2) -> I1 | G77: =VLOOKUP(X77,STORAGE_UNIT_TYPE_MAPPING!A:B,2,FALSE) -> NPALLET-I1 | H77: =TEXT(AE77,"yyyymmdd") -> 20240826 | I77: =TEXT(V77,"yyyymmdd") -> 20250331 | J77: =VLOOKUP(Q77,BIN_MAPPING!A:B,2,FALSE) -> 20-008-1 | K77: 376130313506391289 | L77: CS | M77: 149 | N77: 01 | O77: X | P77: PCK | Q77: 20-08-A | R77: 12552199 | S77: AFTER EIGHT ICON Xmas RAMB 12x57gGB | T77: 376130313506391289 | U77: 41730848 | V77: 45747 | W77: 0001 | X77: LPR | AA77: 149 | AB77: CS | AD77: 45530 | AE77: 45530 | AI77: 118.008
A78: NE00 | B78: BP | C78: NE00 | D78: BP | E78: =VLOOKUP(R78,MATERIAL_MAPPING!A:B,2,FALSE) -> 10569 | F78: =RIGHT(G78,2) -> I1 | G78: =VLOOKUP(X78,STORAGE_UNIT_TYPE_MAPPING!A:B,2,FALSE) -> NPALLET-I1 | H78: =TEXT(AE78,"yyyymmdd") -> 20240913 | I78: =TEXT(V78,"yyyymmdd") -> 20260228 | J78: =VLOOKUP(Q78,BIN_MAPPING!A:B,2,FALSE) -> 20-008-3 | K78: 376130340111458601 | L78: CS | M78: 160 | N78: 01 | O78: X | P78: AG | Q78: 20-08-C | R78: 12502441 | S78: GOURMET MNPT GiG MVChkn37 8(6x50g) N2 GB | T78: 376130340111458601 | U78: 42369718G0 | V78: 46081 | W78: 0001 | X78: CHP | AA78: 160 | AB78: CS | AD78: 45548 | AE78: 45548 | AI78: 435.2
A79: NE00 | B79: BP | C79: NE00 | D79: BP | E79: =VLOOKUP(R79,MATERIAL_MAPPING!A:B,2,FALSE) -> 10803 | F79: =RIGHT(G79,2) -> I1 | G79: =VLOOKUP(X79,STORAGE_UNIT_TYPE_MAPPING!A:B,2,FALSE) -> NPALLET-I1 | H79: =TEXT(AE79,"yyyymmdd") -> 20240823 | I79: =TEXT(V79,"yyyymmdd") -> 20250630 | J79: =VLOOKUP(Q79,BIN_MAPPING!A:B,2,FALSE) -> 20-008-4 | K79: 376130308202770438 | L79: CS | M79: 126 | N79: 01 | O79: X | P79: AG | Q79: 20-08-D | R79: 12591182 | S79: BAKERS Treats Xmas Box 3x458g PR24 XB | T79: 376130308202770438 | U79: 42359766 | V79: 45838 | W79: 0001 | X79: CHP | AA79: 126 | AB79: CS | AD79: 45527 | AE79: 45527 | AI79: 207.144
A80: NE00 | B80: BP | C80: NE00 | D80: BP | E80: =VLOOKUP(R80,MATERIAL_MAPPING!A:B,2,FALSE) -> 10685 | F80: =RIGHT(G80,2) -> I1 | G80: =VLOOKUP(X80,STORAGE_UNIT_TYPE_MAPPING!A:B,2,FALSE) -> NPALLET-I1 | H80: =TEXT(AE80,"yyyymmdd") -> 20241003 | I80: =TEXT(V80,"yyyymmdd") -> 20260331 | J80: =VLOOKUP(Q80,BIN_MAPPING!A:B,2,FALSE) -> 20-008-5 | K80: 350001610370527271 | L80: CS | M80: 28 | N80: 01 | O80: X | P80: AG | Q80: 20-08-E | R80: 12531981 | S80: BETA PUPPY Chicken 14kg N3 XB | T80: 350001610370527271 | U80: 4267093109 | V80: 46112 | W80: 0001 | X80: CHP | AA80: 28 | AB80: EA | AD80: 45568 | AE80: 45568 | AI80: 400.4
A81: NE00 | B81: BP | C81: NE00 | D81: BP | E81: =VLOOKUP(R81,MATERIAL_MAPPING!A:B,2,FALSE) -> 9724 | F81: =RIGHT(G81,2) -> I1 | G81: =VLOOKUP(X81,STORAGE_UNIT_TYPE_MAPPING!A:B,2,FALSE) -> NPALLET-I1 | H81: =TEXT(AE81,"yyyymmdd") -> 20240806 | I81: =TEXT(V81,"yyyymmdd") -> 20250430 | J81: =VLOOKUP(Q81,BIN_MAPPING!A:B,2,FALSE) -> 20-008-6 | K81: 350103475140153893 | L81: CS | M81: 110 | N81: 01 | O81: X | P81: AG | Q81: 20-08-F | R81: 12589604 | S81: MILKYBAR Festive Friend Pouch 5x262g XB | T81: 350103475140153893 | U81: 42130945 | V81: 45777 | W81: 0001 | X81: LPR | AA81: 110 | AB81: CS | AD81: 45510 | AE81: 45510 | AI81: 152.35
A82: NE00 | B82: BP | C82: NE00 | D82: BP | E82: =VLOOKUP(R82,MATERIAL_MAPPING!A:B,2,FALSE) -> 9746 | F82: =RIGHT(G82,2) -> E1 | G82: =VLOOKUP(X82,STORAGE_UNIT_TYPE_MAPPING!A:B,2,FALSE) -> NPALLET-E1 | H82: =TEXT(AE82,"yyyymmdd") -> 20240806 | I82: =TEXT(V82,"yyyymmdd") -> 20250630 | J82: =VLOOKUP(Q82,BIN_MAPPING!A:B,2,FALSE) -> 20-008-8 | K82: 350103450030185697 | L82: CS | M82: 49 | N82: 01 | O82: X | P82: AG | Q82: 20-08-H | R82: 12588254 | S82: NESCAFE CAPPUCCINO Mxd Ty 2.465kg N1 GB | T82: 350103450030185697 | U82: 41909722EA | V82: 45838 | W82: 0001 | X82: EUR | AA82: 49 | AB82: EA | AD82: 45510 | AE82: 45510 | AI82: 169.54
A83: NE00 | B83: BP | C83: NE00 | D83: BP | E83: =VLOOKUP(R83,MATERIAL_MAPPING!A:B,2,FALSE) -> 9758 | F83: =RIGHT(G83,2) -> I1 | G83: =VLOOKUP(X83,STORAGE_UNIT_TYPE_MAPPING!A:B,2,FALSE) -> NPALLET-I1 | H83: =TEXT(AE83,"yyyymmdd") -> 20240816 | I83: =TEXT(V83,"yyyymmdd") -> 20250228 | J83: =VLOOKUP(Q83,BIN_MAPPING!A:B,2,FALSE) -> 20-009-1 | K83: 350103475120221956 | L83: CS | M83: 45 | N83: 01 | O83: X | P83: PCK | Q83: 20-09-A | R83: 12592314 | S83: NESTLE Christmas Slcn Box 10x223.5g XB | T83: 350103475120221956 | U83: 42254826 | V83: 45716 | W83: 0001 | X83: LPR | AA83: 45 | AB83: CS | AD83: 45520 | AE83: 45520 | AI83: 118.665
A84: NE00 | B84: BP | C84: NE00 | D84: BP | E84: =VLOOKUP(R84,MATERIAL_MAPPING!A:B,2,FALSE) -> 8144 | F84: =RIGHT(G84,2) -> E1 | G84: =VLOOKUP(X84,STORAGE_UNIT_TYPE_MAPPING!A:B,2,FALSE) -> NPALLET-E1 | H84: =TEXT(AE84,"yyyymmdd") -> 20240806 | I84: =TEXT(V84,"yyyymmdd") -> 20250525 | J84: =VLOOKUP(Q84,BIN_MAPPING!A:B,2,FALSE) -> 20-009-2 | K84: 340055001841923357 | L84: CS | M84: 80 | N84: 08 | O84: X | P84: AG | Q84: 20-09-B | R84: 12383271 | S84: PEPTAMEN JNRADV Ntr Dual 12x500ml N1 XI | T84: 340055001841923357 | U84: 4151428220 | V84: 45802 | W84: 0001 | X84: EUR | Y84: S | AA84: 80 | AB84: CS | AD84: 45510 | AE84: 45510 | AI84: 536.64
A85: NE00 | B85: BP | C85: NE00 | D85: BP | E85: =VLOOKUP(R85,MATERIAL_MAPPING!A:B,2,FALSE) -> 10406 | F85: =RIGHT(G85,2) -> I1 | G85: =VLOOKUP(X85,STORAGE_UNIT_TYPE_MAPPING!A:B,2,FALSE) -> NPALLET-I1 | H85: =TEXT(AE85,"yyyymmdd") -> 20241008 | I85: =TEXT(V85,"yyyymmdd") -> 20260831 | J85: =VLOOKUP(Q85,BIN_MAPPING!A:B,2,FALSE) -> 20-009-4 | K85: 376130328244492723 | L85: CS | M85: 105 | N85: 01 | O85: X | P85: AG | Q85: 20-09-D | R85: 12445709 | S85: FELIX KTN AGAIL GiJ MVBf 4(12x100g) N2XB | T85: 376130328244492723 | U85: 4264969061 | V85: 46265 | W85: 0001 | X85: CHP | AA85: 105 | AB85: CS | AD85: 45573 | AE85: 45573 | AI85: 567
A86: NE00 | B86: BP | C86: NE00 | D86: BP | E86: =VLOOKUP(R86,MATERIAL_MAPPING!A:B,2,FALSE) -> 9708 | F86: =RIGHT(G86,2) -> I1 | G86: =VLOOKUP(X86,STORAGE_UNIT_TYPE_MAPPING!A:B,2,FALSE) -> NPALLET-I1 | H86: =TEXT(AE86,"yyyymmdd") -> 20241009 | I86: =TEXT(V86,"yyyymmdd") -> 20250731 | J86: =VLOOKUP(Q86,BIN_MAPPING!A:B,2,FALSE) -> 20-009-5 | K86: 350018900021413177 | L86: CS | M86: 18 | N86: 01 | O86: X | P86: AG | Q86: 20-09-E | R86: 12586771 | S86: COOKIE CRISP Cereal 14x500g N4 XB | T86: 350018900021413177 | U86: 42063156 | V86: 45869 | W86: 0001 | X86: LPR | AA86: 18 | AB86: CS | AD86: 45574 | AE86: 45574 | AI86: 145.152
A87: NE00 | B87: BP | C87: NE00 | D87: BP | E87: =VLOOKUP(R87,MATERIAL_MAPPING!A:B,2,FALSE) -> 10932 | F87: =RIGHT(G87,2) -> I1 | G87: =VLOOKUP(X87,STORAGE_UNIT_TYPE_MAPPING!A:B,2,FALSE) -> NPALLET-I1 | H87: =TEXT(AE87,"yyyymmdd") -> 20241004 | I87: =TEXT(V87,"yyyymmdd") -> 20250331 | J87: =VLOOKUP(Q87,BIN_MAPPING!A:B,2,FALSE) -> 20-009-6 | K87: 350103475120207240 | L87: CS | M87: 50 | N87: 01 | O87: X | P87: AG | Q87: 20-09-F | R87: 12503786 | S87: AERO Collection Box 9x360g N1 XB | T87: 350103475120207240 | U87: 42064826 | V87: 45747 | W87: 0001 | X87: LPR | AA87: 50 | AB87: CS | AD87: 45569 | AE87: 45569 | AI87: 208.53
A88: NE00 | B88: BP | C88: NE00 | D88: BP | E88: =VLOOKUP(R88,MATERIAL_MAPPING!A:B,2,FALSE) -> 9306 | F88: =RIGHT(G88,2) -> I1 | G88: =VLOOKUP(X88,STORAGE_UNIT_TYPE_MAPPING!A:B,2,FALSE) -> NPALLET-I1 | H88: =TEXT(AE88,"yyyymmdd") -> 20241003 | I88: =TEXT(V88,"yyyymmdd") -> 20250531 | J88: =VLOOKUP(Q88,BIN_MAPPING!A:B,2,FALSE) -> 20-010-1 | K88: 376130442230151576 | L88: CS | M88: 72 | N88: 01 | O88: X | P88: PCK | Q88: 20-10-A | R88: 12558219 | S88: AFTER EIGHT MintColltnBoxNCP 8x199g N1XB | T88: 376130442230151576 | U88: 42140357 | V88: 45808 | W88: 0001 | X88: LPR | AA88: 72 | AB88: CS | AD88: 45568 | AE88: 45568 | AI88: 132.588
A89: NE00 | B89: BP | C89: NE00 | D89: BP | E89: =VLOOKUP(R89,MATERIAL_MAPPING!A:B,2,FALSE) -> 10430 | F89: =RIGHT(G89,2) -> I1 | G89: =VLOOKUP(X89,STORAGE_UNIT_TYPE_MAPPING!A:B,2,FALSE) -> NPALLET-I1 | H89: =TEXT(AE89,"yyyymmdd") -> 20241008 | I89: =TEXT(V89,"yyyymmdd") -> 20260930 | J89: =VLOOKUP(Q89,BIN_MAPPING!A:B,2,FALSE) -> 20-010-2 | K89: 376130365838982031 | L89: CS | M89: 126 | N89: 01 | O89: X | P89: AG | Q89: 20-10-B | R89: 12448214 | S89: FELIX TASTYSHREDSGIGFrmSlMV4(12x80g)N1GB | T89: 376130365838982031 | U89: 4261969022 | V89: 46295 | W89: 0001 | X89: CHP | AA89: 126 | AB89: CS | AD89: 45573 | AE89: 45573 | AI89: 554.4
A90: NE00 | B90: BP | C90: NE00 | D90: BP | E90: =VLOOKUP(R90,MATERIAL_MAPPING!A:B,2,FALSE) -> 10360 | F90: =RIGHT(G90,2) -> I1 | G90: =VLOOKUP(X90,STORAGE_UNIT_TYPE_MAPPING!A:B,2,FALSE) -> NPALLET-I1 | H90: =TEXT(AE90,"yyyymmdd") -> 20240906 | I90: =TEXT(V90,"yyyymmdd") -> 20251130 | J90: =VLOOKUP(Q90,BIN_MAPPING!A:B,2,FALSE) -> 20-010-3 | K90: 340004875640921885 | L90: CS | M90: 115 | N90: 01 | O90: X | P90: AG | Q90: 20-10-C | R90: 12400025 | S90: BAKERS SIZZLERS Bacon 6x90g XB | T90: 340004875640921885 | U90: 42400695 | V90: 45991 | W90: 0001 | X90: CHP | AA90: 115 | AB90: CS | AD90: 45541 | AE90: 45541 | AI90: 70.38
A91: NE00 | B91: BP | C91: NE00 | D91: BP | E91: =VLOOKUP(R91,MATERIAL_MAPPING!A:B,2,FALSE) -> 10894 | F91: =RIGHT(G91,2) -> I1 | G91: =VLOOKUP(X91,STORAGE_UNIT_TYPE_MAPPING!A:B,2,FALSE) -> NPALLET-I1 | H91: =TEXT(AE91,"yyyymmdd") -> 20240912 | I91: =TEXT(V91,"yyyymmdd") -> 20250531 | J91: =VLOOKUP(Q91,BIN_MAPPING!A:B,2,FALSE) -> 20-010-4 | K91: 376130313505799468 | L91: CS | M91: 168 | N91: 01 | O91: X | P91: AG | Q91: 20-10-D | R91: 12479536 | S91: KITKAT MiniPouch Santa RAMB 12x55g N1 GB | T91: 376130313505799468 | U91: 41410848 | V91: 45808 | W91: 0001 | X91: LPR | AA91: 168 | AB91: CS | AD91: 45547 | AE91: 45547 | AI91: 133.056
A92: NE00 | B92: BP | C92: NE00 | D92: BP | E92: =VLOOKUP(R92,MATERIAL_MAPPING!A:B,2,FALSE) -> 10339 | F92: =RIGHT(G92,2) -> I1 | G92: =VLOOKUP(X92,STORAGE_UNIT_TYPE_MAPPING!A:B,2,FALSE) -> NPALLET-I1 | H92: =TEXT(AE92,"yyyymmdd") -> 20241004 | I92: =TEXT(V92,"yyyymmdd") -> 20260930 | J92: =VLOOKUP(Q92,BIN_MAPPING!A:B,2,FALSE) -> 20-010-5 | K92: 350001612891070069 | L92: CS | M92: 120 | N92: 01 | O92: X | P92: AG | Q92: 20-10-E | R92: 12392576 | S92: WINALOT PRFPORT CiG MVBeef84 40x100g XB | T92: 350001612891070069 | U92: 4276096201 | V92: 46295 | W92: 0001 | X92: CHP | AA92: 120 | AB92: CS | AD92: 45569 | AE92: 45569 | AI92: 552
A93: NE00 | B93: BP | C93: NE00 | D93: BP | E93: =VLOOKUP(R93,MATERIAL_MAPPING!A:B,2,FALSE) -> 9335 | F93: =RIGHT(G93,2) -> I1 | G93: =VLOOKUP(X93,STORAGE_UNIT_TYPE_MAPPING!A:B,2,FALSE) -> NPALLET-I1 | H93: =TEXT(AE93,"yyyymmdd") -> 20241011 | I93: =TEXT(V93,"yyyymmdd") -> 20250531 | J93: =VLOOKUP(Q93,BIN_MAPPING!A:B,2,FALSE) -> 20-010-6 | K93: 376130308202813180 | L93: CS | M93: 208 | N93: 01 | O93: X | P93: AG | Q93: 20-10-F | R93: 12558959 | S93: MILKYBAR BUTTONS Bag 48x30g N1 XB | T93: 376130308202813180 | U93: 42134826 | V93: 45808 | W93: 0001 | X93: LPR | AA93: 208 | AB93: CS | AD93: 45576 | AE93: 45576 | AI93: 309.833
A94: NE00 | B94: BP | C94: NE00 | D94: BP | E94: =VLOOKUP(R94,MATERIAL_MAPPING!A:B,2,FALSE) -> 9708 | F94: =RIGHT(G94,2) -> I1 | G94: =VLOOKUP(X94,STORAGE_UNIT_TYPE_MAPPING!A:B,2,FALSE) -> NPALLET-I1 | H94: =TEXT(AE94,"yyyymmdd") -> 20241002 | I94: =TEXT(V94,"yyyymmdd") -> 20250731 | J94: =VLOOKUP(Q94,BIN_MAPPING!A:B,2,FALSE) -> 20-010-8 | K94: 350018900021413467 | L94: CS | M94: 18 | N94: 01 | O94: X | P94: AG | Q94: 20-10-H | R94: 12586771 | S94: COOKIE CRISP Cereal 14x500g N4 XB | T94: 350018900021413467 | U94: 42063156 | V94: 45869 | W94: 0001 | X94: LPR | AA94: 18 | AB94: CS | AD94: 45567 | AE94: 45567 | AI94: 145.152
A95: NE00 | B95: BP | C95: NE00 | D95: BP | E95: =VLOOKUP(R95,MATERIAL_MAPPING!A:B,2,FALSE) -> 9550 | F95: =RIGHT(G95,2) -> I1 | G95: =VLOOKUP(X95,STORAGE_UNIT_TYPE_MAPPING!A:B,2,FALSE) -> NPALLET-I1 | H95: =TEXT(AE95,"yyyymmdd") -> 20240808 | I95: =TEXT(V95,"yyyymmdd") -> 20250430 | J95: =VLOOKUP(Q95,BIN_MAPPING!A:B,2,FALSE) -> 20-011-1 | K95: 384101007340714375 | L95: CS | M95: 37 | N95: 01 | O95: X | P95: PCK | Q95: 20-11-A | R95: 12576264 | S95: DAIRY BOX Xmas Colltn 8x385g PR 2024 GB | T95: 384101007340714375 | U95: 42120291A | V95: 45777 | W95: 0001 | X95: LPR | AA95: 37 | AB95: CS | AD95: 45512 | AE95: 45512 | AI95: 155.696
A96: NE00 | B96: BP | C96: NE00 | D96: BP | E96: =VLOOKUP(R96,MATERIAL_MAPPING!A:B,2,FALSE) -> 10772 | F96: =RIGHT(G96,2) -> I1 | G96: =VLOOKUP(X96,STORAGE_UNIT_TYPE_MAPPING!A:B,2,FALSE) -> NPALLET-I1 | H96: =TEXT(AE96,"yyyymmdd") -> 20241004 | I96: =TEXT(V96,"yyyymmdd") -> 20260630 | J96: =VLOOKUP(Q96,BIN_MAPPING!A:B,2,FALSE) -> 20-011-2 | K96: 350001612890437139 | L96: CS | M96: 45 | N96: 01 | O96: X | P96: AG | Q96: 20-11-B | R96: 12583654 | S96: FELIX CiJ MV FishSelection 1(80x85g)N1XB | T96: 350001612890437139 | U96: 4166096211 | V96: 46203 | W96: 0001 | X96: CHP | AA96: 45 | AB96: CS | AD96: 45569 | AE96: 45569 | AI96: 351
...

Sheet MATERIAL_MAPPING
A1: LEGACY MATERIAL | B1: BRAVO MATERIAL | C1: OWNER | D1: UOM
A2: 12539973 | B2: 11027 | C2: NE00 | D2: CS
A3: 12536165 | B3: 11026 | C3: NE00 | D3: CS
A4: 12526150 | B4: 11025 | C4: NE00 | D4: CS
A5: 12429567 | B5: 11024 | C5: NE00 | D5: CS
A6: 12512910 | B6: 11023 | C6: NE00 | D6: CS
A7: 12396791 | B7: 11022 | C7: NE00 | D7: CS
A8: 12441088 | B8: 11021 | C8: NE00 | D8: CS
A9: 12396751 | B9: 11020 | C9: NE00 | D9: CS
A10: 12468419 | B10: 11019 | C10: NE00 | D10: CS
A11: 12507636 | B11: 11018 | C11: NE00 | D11: CS
A12: 12536129 | B12: 11017 | C12: NE00 | D12: CS
A13: 12564548 | B13: 11016 | C13: NE00 | D13: CS
... A2938: 12536707 | B2938: 7881 | C2938: NE00 | D2938: CS

Sheet HU_MAPPING
A1: SUT | B1: HU TYPE | C1: PACK MATERIAL
A2: P1 | B2: I1 | C2: NPALLET-I1
A3: P2 | B3: I2 | C3: NPALLET-I1
A4: P3 | B4: I3 | C4: NPALLET-I1

Sheet COLUMN_MAPPING
A1: POSTYPE | B1: MATNR | C1: OWNER | D1: OWNER_ROLE | E1: BATCH | F1: CAT | G1: STOCK_DOCCAT | H1: STOCK_DOCNO | I1: STOCK_ITMNO | J1: STOCK_USAGE | K1: ENTITELED | L1: ENTITLED_ROLE | M1: COO | N1: QUAN | O1: UNIT | P1: HUTYP | Q1: LGPLA | R1: GR_DATE | S1: GR_TIME | T1: VFDAT | U1: PMAT | V1: EXTNO | W1: HUIDENT | X1: PARHUIDENT | Y1: TOPHUIDENT | Z1: ROW | AA1: REFROW | AB1: G_WEIGHT | AC1: N_WEIGHT | AD1: UNIT_GW | AE1: T_WEIGHT | AF1: UNIT_TW | AG1: G_VOLUME | AH1: N_VOLUME | AI1: UNIT_GV | AJ1: T_VOLUME | AK1: UNIT_TV | AL1: G_CAPA | AM1: N_CAPA | AN1: T_CAPA | AO1: LENGTH | AP1: WIDTH | AQ1: HEIGHT | AR1: UNIT_LWH | AS1: MAX_WEIGHT | AT1: TOLW | AU1: TARE_VAR | AV1: MAX_VOLUME | AW1: TOLV | AX1: CLOSED_PACKAGE | AY1: MAX_CAPA | AZ1: MAX_LENGTH | BA1: MAX_WIDTH | BB1: MAX_HEIGHT | BC1: UNIT_MAX_LWH | BD1: SERNR | BE1: CWQUAN | BF1: CWUNIT | BG1: CWEXACT | BH1: LOGPOS | BI1: UII | BJ1: AMOUNT_LC | BK1: DUMMY_ISU | BL1: ZEUGN
A2: MT | B2: MT | C2: MT | D2: MT | E2: MT | F2: MT | G2: MT | H2: MT | I2: MT | J2: MT | K2: MT | L2: MT | M2: MT | N2: MT | O2: MT | P2: F | Q2: J | R2: MT | S2: MT | T2: MT | U2: G | V2: O | W2: K | X2: K | Y2: K | Z2: MT | AA2: MT | AB2: MT | AC2: MT | AD2: MT | AE2: MT | AF2: MT | AG2: MT | AH2: MT | AI2: MT | AJ2: MT | AK2: MT | AL2: MT | AM2: MT | AN2: MT | AO2: MT | AP2: MT | AQ2: MT | AR2: MT | AS2: MT | AT2: MT | AU2: MT | AV2: MT | AW2: MT | AX2: MT | AY2: MT | AZ2: MT | BA2: MT | BB2: MT | BC2: MT | BD2: MT | BE2: MT | BF2: MT | BG2: MT | BH2: MT | BI2: MT | BJ2: MT | BK2: MT | BL2: MT
A3: MT | B3: E | C3: A | D3: B | E3: P | F3: N | G3: MT | H3: MT | I3: MT | J3: MT | K3: C | L3: D | M3: MT | N3: M | O3: L | P3: MT | Q3: J | R3: H | S3: MT | T3: I | U3: MT | V3: MT | W3: K | X3: K | Y3: K | Z3: MT | AA3: MT | AB3: MT | AC3: MT | AD3: MT | AE3: MT | AF3: MT | AG3: MT | AH3: MT | AI3: MT | AJ3: MT | AK3: MT | AL3: MT | AM3: MT | AN3: MT | AO3: MT | AP3: MT | AQ3: MT | AR3: MT | AS3: MT | AT3: MT | AU3: MT | AV3: MT | AW3: MT | AX3: MT | AY3: MT | AZ3: MT | BA3: MT | BB3: MT | BC3: MT | BD3: MT | BE3: MT | BF3: MT | BG3: MT | BH3: MT | BI3: MT | BJ3: MT | BK3: MT | BL3: MT
A8: Migration Schema
A9: MIGRATION COLUMN LABEL
A10: HU COLUMN INDEX
A11: MATERIAL COLUMN INDEX

Sheet CATEGORY_MAPPING
A1: OLD CATEGORY | B1: NEW CATEGORY
B2: 01
A3: S | B3: 08

Sheet BIN_MAPPING
A1: OLD_BIN | B1: NEW_BIN
B2: 19-001-1
B3: 19-002-1
B4: 19-003-1
B5: 19-004-1
B6: 19-005-1
B7: 19-006-1
B8: 19-007-1
B9: 19-008-1
B10: 19-009-1
B11: 19-010-1
B12: 19-011-1
B13: 19-012-1
... B40: 19-039-1
A41: 19-40-A | B41: 19-040-1
A42: 19-41-A | B42: 19-041-1
A43: 19-42-A | B43: 19-042-1
A44: 19-43-A | B44: 19-043-1
A45: 19-44-A | B45: 19-044-1
A46: 19-45-A | B46: 19-045-1
A47: 19-46-A | B47: 19-046-1
A48: 19-47-A | B48: 19-047-1
A49: 19-48-A | B49: 19-048-1
A50: 19-49-A | B50: 19-049-1
A51: 19-50-A | B51: 19-050-1
A52: 19-51-A | B52: 19-051-1
... A1072: 21-39-H | B1072: 21-039-9
B1073: 21-040-1
B1074: 21-040-2
B1075: 21-040-3
B1076: 21-040-4
A1077: 21-39-E1 | B1077: 21-040-5
A1078: 21-39-F1 | B1078: 21-040-6
A1079: 21-39-G1 | B1079: 21-040-7
A1080: 21-39-H1 | B1080: 21-040-8
B1081: 21-041-1
B1082: 21-041-2
B1083: 21-041-3
B1084: 21-041-4
A1085: 21-39-E2 | B1085: 21-041-5
...

Sheet STORAGE_UNIT_TYPE_MAPPING
A1: LPR | B1: NPALLET-I1
A2: CHP | B2: NPALLET-I1
A3: EUR | B3: NPALLET-E1

Sheet FIXED_BIN_TEMPLATE
A1: WAREHOUSE | B1: DISPOSAL | C1: Storage Bin | D1: Storage Type | E1: Product | F1: Max. Qty | G1: UoM | H1: Min. Qty | I1: UoM | J1: Fixed
A2: 5000 | B2: NE00 | C2: 19-043-1 | D2: 3101 | E2: 8064 | F2: 42 | G2: CV | H2: 0 | I2: CV | J2: X
A3: 5000 | B3: NE00 | C3: 19-044-1 | D3: 3101 | E3: 8066 | F3: 42 | G3: CV | H3: 0 | I3: CV | J3: X
A4: 5000 | B4: NE00 | C4: 19-045-1 | D4: 3101 | E4: 8506 | F4: 72 | G4: CV | H4: 0 | I4: CV | J4: X
A5: 5000 | B5: NE00 | C5: 19-046-1 | D5: 3101 | E5: 8440 | F5: 70 | G5: CV | H5: 0 | I5: CV | J5: X
A6: 5000 | B6: NE00 | C6: 19-047-1 | D6: 3101 | E6: 8539 | F6: 80 | G6: CV | H6: 0 | I6: CV | J6: X
A7: 5000 | B7: NE00 | C7: 19-048-1 | D7: 3101 | E7: 8142 | F7: 70 | G7: CV | H7: 0 | I7: CV | J7: X
A8: 5000 | B8: NE00 | C8: 19-049-1 | D8: 3101 | E8: 8504 | F8: 72 | G8: CV | H8: 0 | I8: CV | J8: X
A9: 5000 | B9: NE00 | C9: 19-050-1 | D9: 3101 | E9: 8156 | F9: 90 | G9: CV | H9: 0 | I9: CV | J9: X
A10: 5000 | B10: NE00 | C10: 19-051-1 | D10: 3101 | E10: 10883 | F10: 72 | G10: CV | H10: 0 | I10: CV | J10: X
A11: 5000 | B11: NE00 | C11: 19-052-1 | D11: 3101 | E11: 8143 | F11: 80 | G11: CV | H11: 0 | I11: CV | J11: X
A12: 5000 | B12: NE00 | C12: 19-053-1 | D12: 3101 | E12: 10913 | F12: 80 | G12: CV | H12: 0 | I12: CV | J12: X
A13: 5000 | B13: NE00 | C13: 19-054-1 | D13: 3101 | E13: 8141 | F13: 80 | G13: CV | H13: 0 | I13: CV | J13: X
A14: 5000 | B14: NE00 | C14: 19-055-1 | D14: 3101 | E14: #N/A | F14: 80 | G14: CV | H14: 0 | I14: CV | J14: X
A15: 5000 | B15: NE00 | C15: 19-056-1 | D15: 3101 | E15: 8144 | F15: 80 | G15: CV | H15: 0 | I15: CV | J15: X
A16: 5000 | B16: NE00 | C16: 19-057-1 | D16: 3101 | E16: 10888 | F16: 80 | G16: CV | H16: 0 | I16: CV | J16: X
A17: 5000 | B17: NE00 | C17: 19-058-1 | D17: 3101 | E17: 8154 | F17: 90 | G17: CV | H17: 0 | I17: CV | J17: X
A18: 5000 | B18: NE00 | C18: 19-059-1 | D18: 3101 | E18: 9303 | F18: 96 | G18: CV | H18: 0 | I18: CV | J18: X
A19: 5000 | B19: NE00 | C19: 19-060-1 | D19: 3101 | E19: 10917 | F19: 80 | G19: CV | H19: 0 | I19: CV | J19: X
A20: 5000 | B20: NE00 | C20: 19-061-1 | D20: 3101 | E20: 9334 | F20: 54 | G20: CV | H20: 0 | I20: CV | J20: X
A21: 5000 | B21: NE00 | C21: 19-062-1 | D21: 3101 | E21: 8068 | F21: 84 | G21: CV | H21: 0 | I21: CV | J21: X
A22: 5000 | B22: NE00 | C22: 19-063-1 | D22: 3101 | E22: 10919 | F22: 120 | G22: CV | H22: 0 | I22: CV | J22: X
A23: 5000 | B23: NE00 | C23: 19-064-1 | D23: 3101 | E23: 9791 | F23: 160 | G23: CV | H23: 0 | I23: CV | J23: X
A24: 5000 | B24: NE00 | C24: 19-065-1 | D24: 3101 | E24: 7894 | F24: 70 | G24: CV | H24: 0 | I24: CV | J24: X
A25: 5000 | B25: NE00 | C25: 19-066-1 | D25: 3101 | E25: 8256 | F25: 90 | G25: CV | H25: 0 | I25: CV | J25: X
A26: 5000 | B26: NE00 | C26: 19-067-1 | D26: 3101 | E26: 9390 | F26: 160 | G26: CV | H26: 0 | I26: CV | J26: X
... A135: 5000 | B135: NE00 | C135: 21-022-1 | D135: 3101 | E135: 10577 | F135: 120 | G135: CV | H135: 0 | I135: CV | J135: X
A136: 5000 | B136: NE00 | C136: 21-023-1 | D136: 3101 | E136: #N/A | F136: 126 | G136: CV | H136: 0 | I136: CV | J136: X
A137: 5000 | B137: NE00 | C137: 21-024-1 | D137: 3101 | E137: 10759 | F137: 120 | G137: CV | H137: 0 | I137: CV | J137: X
A138: 5000 | B138: NE00 | C138: 21-025-1 | D138: 3101 | E138: 10701 | F138: 126 | G138: CV | H138: 0 | I138: CV | J138: X
A139: 5000 | B139: NE00 | C139: 21-026-1 | D139: 3101 | E139: 10703 | F139: 126 | G139: CV | H139: 0 | I139: CV | J139: X
A140: 5000 | B140: NE00 | C140: 21-027-1 | D140: 3101 | E140: 10944 | F140: 126 | G140: CV | H140: 0 | I140: CV | J140: X
A141: 5000 | B141: NE00 | C141: 21-028-1 | D141: 3101 | E141: 10704 | F141: 114 | G141: CV | H141: 0 | I141: CV | J141: X
A142: 5000 | B142: NE00 | C142: 21-029-1 | D142: 3101 | E142: 10741 | F142: 105 | G142: CV | H142: 0 | I142: CV | J142: X
A143: 5000 | B143: NE00 | C143: 21-030-1 | D143: 3101 | E143: 10569 | F143: 160 | G143: CV | H143: 0 | I143: CV | J143: X
A144: 5000 | B144: NE00 | C144: 21-031-1 | D144: 3101 | E144: 10641 | F144: 160 | G144: CV | H144: 0 | I144: CV | J144: X
A145: 5000 | B145: NE00 | C145: 21-032-1 | D145: 3101 | E145: 10570 | F145: 160 | G145: CV | H145: 0 | I145: CV | J145: X
A146: 5000 | B146: NE00 | C146: 21-033-1 | D146: 3101 | E146: 10567 | F146: 120 | G146: CV | H146: 0 | I146: CV | J146: X
A147: 5000 | B147: NE00 | C147: 21-034-1 | D147: 3101 | E147: 10572 | F147: 160 | G147: CV | H147: 0 | I147: CV | J147: X
A148: 5000 | B148: NE00 | C148: 21-035-1 | D148: 3101 | E148: 10568 | F148: 120 | G148: CV | H148: 0 | I148: CV | J148: X
...
